Workbook

Sheet 2019
A1: Sr No | B1: Name of the Employee | C1: Salary | D1: Bonus amount | E1: Reporting manager | F1: March | G1: April | H1: May | I1: June | J1: July | K1: August | L1: Sept | M1: Oct | N1: Nov | O1: Dec | P1: TOTAL | Q1: Paid Amount | R1: hold bonus
A2: 1 | B2: Mariyam | C2: 15000 | D2: 5000 | E2: Kaniz Fatema | F2: 5000 | G2: 5000 | H2: 5000 | I2: 5000 | J2: 4000 | K2: 2000 | L2: 4000 | M2: 2500 | N2: 5000 | O2: 5000 | P2: =SUM(F2:O2) -> 42500 | R2: =SUM(F2:O2) -> 42500
A3: 2 | B3: Nagma Khan | C3: 17000 | D3: 5000 | E3: Akbar sir | F3: 5000 | G3: 5000 | H3: 5000 | I3: 5000 | J3: 5000 | K3: 4500 | L3: 5000 | M3: 5000 | N3: 5000 | O3: 5000 | P3: =SUM(F3:O3) -> 49500 | R3: =SUM(F3:O3) -> 49500
A4: 3 | B4: Kaniz Fatema | C4: 25000 | D4: 5000 | E4: Avesh | F4: 5000 | G4: 5000 | H4: 5000 | I4: 5000 | J4: 5000 | K4: 5000 | L4: 5000 | M4: 5000 | N4: 5000 | O4: 5000 | P4: =SUM(F4:O4) -> 50000 | R4: =SUM(F4:O4) -> 50000
A5: 4 | B5: Shaikh Mohd Salman | C5: 10000 | D5: 5000 | E5: Kaniz Fatema | F5: 4000 | G5: 4000 | H5: 4000 | I5: 5000 | J5: 4000 | K5: 3000 | L5: 3000 | M5: 3200 | N5: 2500 | O5: 3500 | P5: =SUM(F5:O5) -> 36200 | R5: =SUM(F5:O5) -> 36200
A6: 5 | B6: Shahrukh Siddiqui | C6: 6000 | D6: 4000 | E6: Kaniz Fatema | F6: 0 | G6: 0 | H6: 0 | I6: 0 | J6: 3200 | K6: 3000 | L6: 0 | M6: 3500 | N6: 3500 | O6: 3000 | P6: =SUM(F6:O6) -> 16200 | R6: =SUM(F6:O6) -> 16200
A7: 6 | B7: Musharraf Siddiqui | C7: 25000 | D7: 5000 | E7: Akbar sir | F7: 4000 | G7: 4000 | H7: 4000 | I7: 5000 | J7: 5000 | K7: 5000 | L7: 5000 | M7: 5000 | N7: 5000 | O7: 5000 | P7: =SUM(F7:O7) -> 47000 | R7: =SUM(F7:O7) -> 47000
A8: 7 | B8: Nabeela Khan | C8: 25000 | D8: 4000 | E8: Akbar sir | F8: 4000 | G8: 4000 | H8: 4000 | I8: 4000 | J8: 4500 | K8: 5000 | L8: 5000 | M8: 5000 | N8: 5000 | O8: 5000 | P8: =SUM(F8:O8) -> 45500 | R8: =SUM(F8:O8) -> 45500
A9: 8 | B9: Rehanuddin Mohd | C9: 15000 | D9: 5000 | E9: Kaniz Fatema | F9: 4000 | G9: 4000 | H9: 4000 | I9: 4000 | J9: 3500 | K9: 3000 | L9: 4000 | M9: 5000 | N9: 4000 | O9: 5000 | P9: =SUM(F9:O9) -> 40500 | R9: =SUM(F9:O9) -> 40500
A10: 9 | B10: Shaikh Sameer | C10: 10000 | D10: 5000 | E10: Kaniz Fatema | F10: 5000 | G10: 5000 | H10: 5000 | I10: 5000 | J10: 4000 | K10: 3000 | L10: 3000 | M10: 2500 | N10: 3500 | O10: NA | P10: =SUM(F10:O10) -> 36000 | Q10: Not paid | R10: =SUM(F10:O10) -> 36000
A11: 10 | B11: Shaihk Fares | C11: 10000 | D11: 5000 | E11: Kaniz Fatema | F11: 5000 | G11: 5000 | H11: 5000 | I11: 5000 | J11: 4000 | K11: 3000 | L11: 4000 | M11: 0 | N11: 3500 | O11: 5000 | P11: =SUM(F11:O11)-Q11 -> 14500 | Q11: 25000 | R11: =SUM(F11:O11)-Q11 -> 14500
A12: 11 | B12: Aameruddin | C12: 10000 | D12: 4000 | E12: Akbar sir | F12: NA | G12: NA | H12: NA | I12: NA | J12: 4000 | K12: 4000 | L12: 2600 | M12: 3000 | N12: 0 | O12: 0 | P12: =SUM(F12:O12) -> 13600 | R12: =SUM(F12:O12) -> 13600
A13: 12 | B13: shahid quadri | C13: 16000 | D13: 4000 | E13: Kaniz Fatema | F13: 4000 | G13: 4000 | H13: 4000 | I13: 4000 | J13: 3200 | K13: 3000 | L13: 2000 | M13: 5000 | N13: 5000 | O13: 5000 | P13: =SUM(F13:O13)-Q13 -> 23200 | Q13: 16000 | R13: =SUM(F13:O13)-Q13 -> 23200
A14: 13 | B14: Sayyed Amjad | C14: 16000 | D14: 4000 | E14: Kaniz Fatema | F14: 4000 | G14: 4000 | H14: 4000 | I14: 4000 | J14: 3500 | K14: 3500 | L14: 3500 | M14: 0 | P14: =SUM(F14:O14) -> 26500 | Q14: =P14 -> 26500 | R14: =SUM(F14:O14)-Q14 -> 0
A15: 14 | B15: Mustaqueem | C15: 16000 | D15: 4000 | E15: Akbar sir | F15: NA | G15: NA | H15: NA | I15: NA | J15: 4000 | K15: 4000 | L15: 4000 | M15: 4000 | N15: 4000 | O15: 4000 | P15: =SUM(F15:O15) -> 24000 | R15: =SUM(F15:O15) -> 24000
A16: 15 | B16: Irteqaz ahmed | C16: 12000 | D16: 4000 | E16: Akbar sir | F16: NA | G16: NA | H16: NA | I16: NA | J16: 4000 | K16: 3000 | L16: 2800 | M16: 0 | P16: =SUM(F16:O16) -> 9800 | Q16: =P16 -> 9800 | R16: =SUM(F16:O16)-Q16 -> 0
A17: 16 | B17: Shaikh Saifullah | C17: 10000 | D17: 4000 | E17: Kaniz Fatema | F17: NA | G17: NA | H17: NA | I17: 4000 | J17: 4000 | K17: 3000 | L17: 3500 | M17: 3500 | N17: 3000 | O17: 4000 | P17: =SUM(F17:O17) -> 25000 | R17: =SUM(F17:O17) -> 25000
A18: 17 | B18: Shah Alam | C18: 6000 | D18: 6000 | E18: Akbar sir | F18: NA | G18: NA | H18: NA | I18: 6000 | J18: 6000 | K18: 6000 | L18: 6000 | M18: 6000 | N18: 6000 | O18: 6000 | P18: =SUM(F18:O18)-Q18 -> 0 | Q18: =SUM(I18:O18) -> 42000 | R18: =SUM(F18:O18)-Q18 -> 0
A19: 18 | B19: Shamshad | C19: 6000 | D19: 3000 | E19: Akbar sir | F19: NA | G19: NA | H19: NA | I19: NA | J19: NA | K19: NA | L19: NA | M19: NA | N19: 2000 | O19: 2000 | P19: =SUM(F19:O19) -> 4000 | R19: =SUM(F19:O19) -> 4000
A20: 19 | B20: Shaikh Tareq | C20: 6000 | D20: 5000 | E20: Akbar sir | L20: 2000 | M20: 2500 | N20: 3000 | O20: 3000 | P20: =SUM(F20:O20) -> 10500 | R20: =SUM(F20:O20) -> 10500
A21: 20 | B21: Vasim Shaikh | C21: 6000 | D21: 4000 | E21: Akbar sir | M21: 3000 | N21: 2500 | O21: 0 | P21: =SUM(F21:O21) -> 5500 | R21: =SUM(F21:O21) -> 5500
J23: =P13-Q13 -> 7200 | N23: TOTAL | P23: =SUM(P2:P21) -> 520000
C25: Paid with salary
C26: Paid in advance
C27: Paid Total amount
B28: Not applicable for this month | C28: NA

Sheet 2020
A1: Sr No | C1: Technology | D1: Salary | E1: Bonus amount | F1: Reporting manager | G1: Jan | H1: Feb | I1: Mar | J1: Apr | K1: May | L1: Jun | M1: Jul | N1: Aug | O1: Sep | P1: Oct | Q1: Nov | R1: Dec | S1: This year 2020 | T1: Previous year 2019 total | U1: TOTAL | V1: 2 Months salary | W1: Yearly Permissible Bonus amount | X1: Paid Amount | Y1: To be Paid with Salary in May | Z1: To be Paid with Salary in June | AA1: To be Paid with Salary in July | AB1: To be Paid with Salary in August | AC1: To be Paid with Salary in September | AD1: To be Paid with Salary in October | AE1: To be Paid with Salary in November | AF1: To be Paid with Salary in December | AG1: Total bonus given in 2020 amount | AH1: Remaining Bonus amount in dec 2020
A2: 1 | B2: Mariyam | C2: Salesforce | D2: 20000 | E2: 10000 | F2: Kaniz Fatema | G2: 5000 | H2: 5000 | I2: 4500 | J2: 4000 | K2: 3000 | L2: 0 | M2: 3000 | N2: 3500 | O2: 0 | P2: 7000 | Q2: 7000 | R2: 7000 | S2: =SUM(G2:R2) -> 49000 | T2: ='2019'!P2 -> 42500 | U2: =S2+T2 -> 91500 | V2: =D2*2 -> 40000 | W2: =U2-V2 -> 51500 | Y2: 3000 | Z2: 0 | AA2: 3000 | AB2: =N2 -> 3500 | AC2: =O2 -> 0 | AD2: =P2 -> 7000 | AE2: =Q2 -> 7000 | AF2: =R2 -> 7000 | AG2: =SUM(Y2:AF2) -> 30500 | AH2: =W2-AG2 -> 21000
A3: 2 | B3: Kaniz Fatema | C3: Salesforce | D3: 30000 | E3: 5000 | F3: Akbar sir | G3: 5000 | H3: 5000 | I3: 5000 | J3: 5000 | K3: 5000 | L3: 5000 | M3: 5000 | N3: 5000 | O3: 2500 | P3: 5000 | Q3: 5000 | R3: 5000 | S3: =SUM(G3:R3) -> 57500 | T3: ='2019'!P4 -> 50000 | U3: =S3+T3 -> 107500 | V3: =D3*2 -> 60000 | W3: =U3-V3 -> 47500 | Y3: 5000 | Z3: 5000 | AA3: 5000 | AB3: =N3 -> 5000 | AC3: =O3 -> 2500 | AD3: =P3 -> 5000 | AE3: =Q3 -> 5000 | AF3: =R3 -> 5000 | AG3: =SUM(Y3:AF3) -> 37500 | AH3: =W3-AG3 -> 10000
A4: 3 | B4: Sayyed Manzar Ali | C4: Uipath | D4: 20000 | E4: 10000 | F4: Akbar sir | G4: NA | H4: NA | I4: 4000 | J4: 4000 | K4: 4000 | L4: 4000 | M4: 4000 | N4: 4000 | O4: 4000 | P4: 4000 | Q4: 10000 | R4: 10000 | S4: =SUM(G4:R4) -> 52000 | T4: 0 | U4: =S4+T4 -> 52000 | V4: =D4*2 -> 40000 | W4: =U4-V4 -> 12000 | Y4: NA | Z4: 0 | AA4: 0 | AB4: 0 | AC4: 0 | AF4: =R4 -> 10000 | AG4: =SUM(Y4:AF4) -> 10000 | AH4: =W4-AG4 -> 2000
A5: 4 | B5: Zeeshan Sayyed | C5: OIC | D5: 10000 | E5: 2000 | F5: Akbar sir | G5: NA | H5: 0 | I5: 0 | J5: 0 | L5: 2000 | M5: 2000 | N5: 2000 | O5: 0 | P5: 2000 | Q5: 2000 | R5: 2000 | S5: =SUM(G5:R5) -> 12000 | T5: 0 | U5: =S5+T5 -> 12000 | V5: =D5*2 -> 20000 | W5: =U5-V5 -> -8000 | Y5: NA | Z5: 0 | AA5: 0 | AB5: 0 | AC5: =O5 -> 0 | AG5: =SUM(Y5:AF5) -> 0 | AH5: =S5 -> 12000
A6: 5 | B6: Shah Alam | C6: Web development | D6: 15000 | E6: 10000 | F6: Akbar sir | G6: 6000 | H6: 6000 | I6: 6000 | J6: 3000 | K6: 3000 | L6: 3000 | M6: 5000 | N6: 5000 | O6: 5000 | P6: 5000 | Q6: 8000 | R6: 8000 | S6: =SUM(G6:R6) -> 63000 | T6: 0 | U6: =S6+T6 -> 63000 | V6: =D6*2 -> 30000 | W6: =U6-V6 -> 33000 | X6: =SUM(G6:H6)+J6+K6 -> 18000 | Y6: 3000 | Z6: 0 | AA6: 0 | AB6: =N6 -> 5000 | AC6: =O6 -> 5000 | AD6: =P6 -> 5000 | AE6: =Q6 -> 8000 | AF6: =R6 -> 8000 | AG6: =SUM(Y6:AF6) -> 34000 | AH6: =W6-AG6 -> -1000
A7: 6 | B7: Sayyed Haider | C7: SharePoint | D7: 10000 | E7: 10000 | F7: Akbar sir | G7: NA | H7: 4000 | I7: 4000 | J7: 2000 | K7: 4000 | L7: 4000 | M7: 4000 | N7: 4000 | O7: 2000 | P7: 3000 | Q7: 10000 | R7: 10000 | S7: =SUM(G7:R7) -> 51000 | T7: 0 | U7: =S7+T7 -> 51000 | V7: =D7*2 -> 20000 | W7: =U7-V7 -> 31000 | Y7: NA | Z7: 0 | AA7: 0 | AB7: =N7 -> 4000 | AC7: =O7 -> 2000 | AD7: =P7 -> 3000 | AE7: =Q7 -> 10000 | AF7: =R7 -> 10000 | AG7: =SUM(Y7:AF7) -> 29000 | AH7: =W7-AG7 -> 2000
A8: 7 | B8: Saba Shaikh | C8: SharePoint | D8: 10000 | E8: 10000 | F8: Akbar sir | G8: NA | H8: 4000 | I8: 4000 | J8: 2000 | K8: 4000 | L8: 4000 | M8: 4000 | N8: 4000 | O8: 4000 | P8: 4000 | Q8: 10000 | R8: 5000 | S8: =SUM(G8:R8) -> 49000 | T8: 0 | U8: =S8+T8 -> 49000 | V8: =D8*2 -> 20000 | W8: =U8-V8 -> 29000 | Y8: NA | Z8: 0 | AA8: 0 | AB8: 0 | AC8: =O8 -> 4000 | AD8: =P8 -> 4000 | AE8: =Q8 -> 10000 | AF8: =R8 -> 5000 | AG8: =SUM(Y8:AF8) -> 23000 | AH8: =W8-AG8 -> 6000
A9: 8 | B9: Shahrukh Siddiqui | C9: Salesforce | D9: 15000 | E9: 10000 | F9: Kaniz Fatema | G9: 4000 | H9: 3000 | I9: 3000 | J9: 4000 | K9: 3000 | L9: 3000 | M9: 3000 | N9: 2000 | O9: 7500 | P9: 6000 | Q9: 7000 | R9: 7000 | S9: =SUM(G9:R9) -> 52500 | T9: ='2019'!P6 -> 16200 | U9: =S9+T9 -> 68700 | V9: =D9*2 -> 30000 | W9: =U9-V9 -> 38700 | Y9: 3000 | Z9: 3000 | AA9: 3000 | AB9: =N9 -> 2000 | AC9: =O9 -> 7500 | AD9: =P9 -> 6000 | AE9: =Q9 -> 7000 | AF9: =R9 -> 7000 | AG9: =SUM(Y9:AF9) -> 38500 | AH9: =W9-AG9 -> 200
A10: 9 | B10: Shamshad Ahmed | C10: Qliksense | D10: 16000 | E10: 5000 | F10: Akbar sir | G10: 4000 | H10: 0 | I10: 0 | J10: 3000 | K10: 3000 | L10: 4000 | M10: 3000 | N10: =4000+5000 -> 9000 | O10: 4000 | P10: 5000 | Q10: 5000 | R10: 5000 | S10: =SUM(G10:R10) -> 45000 | T10: ='2019'!P19 -> 4000 | U10: =S10+T10 -> 49000 | V10: =D10*2 -> 32000 | W10: =U10-V10 -> 17000 | Y10: NA | Z10: 0 | AA10: 0 | AB10: 4000 | AC10: =O10 -> 4000 | AD10: =P10 -> 5000 | AE10: =Q10 -> 5000 | AF10: =R10 -> 5000 | AG10: =SUM(Y10:AF10) -> 23000 | AH10: =W10-AG10 -> -6000
A11: 10 | B11: Musharrafuddin Siddiqui | C11: Web development | D11: 25000 | E11: 10000 | F11: Akbar sir | G11: 5000 | H11: 2000 | I11: 2000 | J11: 5000 | K11: 5000 | L11: 5000 | M11: 5000 | N11: 5000 | O11: 5000 | P11: 5000 | Q11: 4000 | R11: 0 | S11: =SUM(G11:R11) -> 48000 | T11: ='2019'!P7 -> 47000 | U11: =S11+T11 -> 95000 | V11: =D11*2 -> 50000 | W11: =U11-V11 -> 45000 | Y11: 5000 | Z11: 5000 | AA11: 5000 | AB11: =N11 -> 5000 | AC11: =O11 -> 5000 | AD11: =P11 -> 5000 | AE11: =Q11 -> 4000 | AG11: =SUM(Y11:AF11) -> 34000 | AH11: =W11-AG11 -> 11000
A12: 11 | B12: Shahid Qadri | C12: Salesforce | D12: 25000 | E12: 10000 | F12: Kaniz Fatema | G12: 5000 | H12: 5000 | I12: 4500 | J12: 5000 | K12: 5000 | L12: 1000 | M12: 4000 | N12: 5000 | O12: 8500 | P12: 9000 | Q12: 10000 | R12: 10000 | S12: =SUM(G12:R12) -> 72000 | T12: ='2019'!P13 -> 23200 | U12: =S12+T12 -> 95200 | V12: =D12*2 -> 50000 | W12: =U12-V12 -> 45200 | X12: 16000 | Y12: 5000 | Z12: 1000 | AA12: 4000 | AB12: =N12 -> 5000 | AC12: =O12 -> 8500 | AD12: =P12 -> 9000 | AE12: =Q12 -> 10000 | AF12: =R12 -> 10000 | AG12: =SUM(Y12:AF12) -> 52500 | AH12: =W12-AG12 -> -7300
A13: 12 | B13: Nabeela khan | C13: Microsoft CRM | D13: 25000 | E13: 10000 | F13: Akbar sir | G13: 3000 | H13: 0 | I13: 0 | J13: 3000 | K13: 5000 | L13: 5000 | M13: 5000 | N13: 5000 | O13: 5000 | P13: 5000 | Q13: 10000 | R13: 10000 | S13: =SUM(G13:R13) -> 56000 | T13: ='2019'!P8 -> 45500 | U13: =S13+T13 -> 101500 | V13: =D13*2 -> 50000 | W13: =U13-V13 -> 51500 | Y13: 5000 | Z13: 5000 | AA13: 5000 | AB13: =N13 -> 5000 | AC13: =O13 -> 5000 | AD13: =P13 -> 5000 | AE13: =Q13 -> 10000 | AF13: =R13 -> 10000 | AG13: =SUM(Y13:AF13) -> 50000 | AH13: =W13-AG13 -> 1500
A14: 13 | B14: Mohammad Rehanuddin | C14: Salesforce | D14: 25000 | E14: 10000 | F14: Kaniz Fatema | G14: 5000 | H14: 5000 | I14: 4500 | J14: 5000 | K14: 5000 | L14: 4000 | M14: 5000 | N14: 5000 | O14: 5000 | P14: 9000 | Q14: 8000 | R14: 9000 | S14: =SUM(G14:R14) -> 69500 | T14: ='2019'!P9 -> 40500 | U14: =S14+T14 -> 110000 | V14: =D14*2 -> 50000 | W14: =U14-V14 -> 60000 | Y14: 5000 | Z14: 4000 | AA14: 5000 | AB14: =N14 -> 5000 | AC14: =O14 -> 5000 | AD14: =P14 -> 9000 | AE14: =Q14 -> 8000 | AF14: =R14 -> 9000 | AG14: =SUM(Y14:AF14) -> 50000 | AH14: =W14-AG14 -> 10000
A15: 14 | B15: Shaikh Tareq | C15: Eautomate | D15: 15000 | E15: 5000 | F15: Akbar sir | G15: 3000 | H15: 3000 | I15: 3000 | J15: 3000 | K15: 3000 | L15: 5000 | M15: =5000+0 -> 5000 | N15: 2000 | O15: 2000 | P15: 5000 | Q15: 5000 | R15: 5000 | S15: =SUM(G15:R15) -> 44000 | T15: ='2019'!P20 -> 10500 | U15: =S15+T15 -> 54500 | V15: =D15*2 -> 30000 | W15: =U15-V15 -> 24500 | Y15: 3000 | Z15: 5000 | AA15: =M15 -> 5000 | AB15: =N15 -> 2000 | AC15: =O15 -> 2000 | AD15: =P15 -> 5000 | AE15: =Q15 -> 5000 | AF15: =R15 -> 5000 | AG15: =SUM(Y15:AF15) -> 32000 | AH15: =W15-AG15 -> -7500
A16: 15 | B16: Sohel Shaikh | C16: Microsoft CRM | D16: 6000 | E16: 10000 | F16: Akbar sir | G16: 0 | H16: 0 | I16: 0 | J16: 0 | K16: 0 | L16: 4000 | M16: 10000 | N16: 10000 | O16: 10000 | P16: 10000 | Q16: 10000 | R16: 10000 | S16: =SUM(G16:R16) -> 64000 | T16: 0 | U16: =S16+T16 -> 64000 | V16: =D16*2 -> 12000 | W16: =U16-V16 -> 52000 | Y16: NA | Z16: 0 | AA16: =M16 -> 10000 | AB16: =N16 -> 10000 | AC16: =O16 -> 10000 | AD16: =P16 -> 10000 | AE16: =Q16 -> 10000 | AF16: =R16 -> 10000 | AG16: =SUM(Y16:AF16) -> 60000 | AH16: =W16-AG16 -> -8000
A17: 16 | B17: Irfan Shaikh | C17: Microsoft CRM | D17: 10000 | E17: 4000 | F17: Akbar sir | G17: NA | H17: NA | I17: 4000 | J17: 4000 | K17: 0 | L17: 4000 | M17: 4000 | N17: 2000 | O17: 4000 | P17: 2000 | Q17: 2000 | R17: 4000 | S17: =SUM(G17:R17) -> 30000 | T17: 0 | U17: =S17+T17 -> 30000 | V17: =D17*2 -> 20000 | W17: =U17-V17 -> 10000 | Z17: 4000 | AA17: 20000 | AB17: 0 | AC17: 0 | AF17: =R17 -> 4000 | AG17: =SUM(Y17:AF17) -> 28000 | AH17: =N17+P17+Q17 -> 6000
A18: 17 | B18: Waseem Mohammad | C18: Web development | D18: 6000 | E18: 6000 | F18: Akbar sir | G18: NA | H18: NA | I18: NA | J18: NA | K18: NA | L18: NA | M18: 6000 | N18: 6000 | O18: 5000 | P18: 6000 | Q18: 6000 | R18: 6000 | S18: =SUM(G18:R18) -> 35000 | T18: 0 | U18: =S18+T18 -> 35000 | V18: =D18*2 -> 12000 | W18: =U18-V18 -> 23000 | Z18: 0 | AA18: 0 | AB18: 0 | AC18: =O18 -> 5000 | AD18: =P18 -> 6000 | AE18: =Q18 -> 6000 | AF18: =R18 -> 6000 | AG18: =SUM(Y18:AF18) -> 23000 | AH18: =W18-AG18 -> 0
A19: 18 | B19: Nagma Khan | C19: SharePoint | D19: 17000 | E19: 10000 | F19: Akbar sir | G19: NA | H19: NA | I19: NA | J19: NA | K19: NA | L19: NA | M19: 5000 | N19: 5000 | O19: 5000 | P19: 5000 | Q19: 10000 | R19: 10000 | S19: =SUM(M19:R19) -> 40000 | T19: ='2019'!P3 -> 49500 | U19: =S19+T19 -> 89500 | V19: =D19*2 -> 34000 | W19: =U19-V19 -> 55500 | Z19: 0 | AA19: 0 | AB19: 0 | AC19: =O19 -> 5000 | AG19: =SUM(Y19:AF19) -> 5000 | AH19: =W19-AG19 -> 50500
A20: 19 | B20: Shaikh Mudassir | C20: E-automate | D20: 6000 | E20: 6000 | F20: Akbar sir | G20: NA | H20: NA | I20: NA | J20: NA | K20: NA | L20: NA | M20: =3000+1650 -> 4650 | N20: =3000+3000 -> 6000 | O20: =6000+3000 -> 9000 | P20: =3000+3000 -> 6000 | Q20: 6000 | R20: 6000 | S20: =SUM(G20:R20) -> 37650 | T20: 0 | U20: =S20+T20 -> 37650 | V20: =D20*2 -> 12000 | W20: =U20-V20 -> 25650 | Z20: 0 | AA20: 0 | AB20: 0 | AC20: =O20 -> 9000 | AD20: 3000 | AE20: =Q20 -> 6000 | AF20: =R20 -> 6000 | AG20: =SUM(Y20:AF20) -> 24000 | AH20: =S20-AG20 -> 13650 | AI20: =V20+AH20 -> 25650
A21: 20 | B21: Shaikh Javed | C21: E-automate | D21: 6000 | E21: 6000 | F21: Akbar sir | G21: NA | H21: NA | I21: NA | J21: NA | K21: NA | L21: NA | M21: =3000+1800 -> 4800 | N21: =3000+3000 -> 6000 | O21: =6000+3000 -> 9000 | P21: =3000+3000 -> 6000 | Q21: 6000 | R21: 6000 | S21: =SUM(G21:R21) -> 37800 | T21: 0 | U21: =S21+T21 -> 37800 | V21: =D21*2 -> 12000 | W21: =U21-V21 -> 25800 | Z21: 0 | AA21: 0 | AC21: =O21 -> 9000 | AD21: 3000 | AE21: =E21 -> 6000 | AF21: =R21 -> 6000 | AG21: =SUM(Y21:AF21) -> 24000 | AH21: =S21-AG21 -> 13800 | AI21: =V21-AH21 -> -1800
A22: 21 | B22: Mustaqeem | C22: Salesforce | D22: 20000 | E22: 5000 | F22: Akbar sir | G22: NA | H22: NA | I22: NA | J22: NA | K22: NA | L22: NA | M22: NA | N22: 3000 | O22: 4000 | P22: 5000 | Q22: 5000 | R22: 5000 | S22: =SUM(G22:R22) -> 22000 | T22: ='2019'!P15 -> 24000 | U22: =S22+T22 -> 46000 | V22: =D22*2 -> 40000 | W22: =U22-V22 -> 6000 | Z22: 0 | AA22: 0 | AB22: 0 | AC22: 0 | AG22: =SUM(Y22:AF22) -> 0 | AH22: =W22-AG22 -> 6000
A23: 22 | B23: Maaz Shaokat Choughle | C23: Salesforce | D23: 12000 | E23: 4000 | F23: Akbar sir | G23: NA | H23: NA | I23: NA | J23: NA | K23: NA | L23: NA | M23: NA | N23: NA | O23: 2500 | P23: 4000 | Q23: 3000 | R23: 4000 | S23: =SUM(G23:R23) -> 13500 | T23: 0 | U23: =S23+T23 -> 13500 | V23: =D23*2 -> 24000 | W23: =U23-V23 -> -10500 | Z23: 0 | AA23: 0 | AC23: 0 | AG23: =SUM(Y23:AF23) -> 0 | AH23: =W23-AG23 -> -10500
A24: 23 | B24: Sohail Inamdar | C24: Salesforce | D24: 12000 | E24: 4000 | F24: Akbar sir | G24: NA | H24: NA | I24: NA | J24: NA | K24: NA | L24: NA | M24: NA | N24: NA | O24: 3000 | P24: 2500 | Q24: 3000 | R24: 3000 | S24: =SUM(G24:R24) -> 11500 | T24: 0 | U24: =S24+T24 -> 11500 | V24: =D24*2 -> 24000 | W24: =U24-V24 -> -12500 | Z24: 0 | AA24: 0 | AC24: 0 | AG24: =SUM(Y24:AF24) -> 0 | AH24: =S24 -> 11500
A25: 24 | B25: Ansari Mohd Ateef | C25: Salesforce | D25: 12000 | E25: 4000 | F25: Akbar sir | G25: NA | H25: NA | I25: NA | J25: NA | K25: NA | L25: NA | M25: NA | N25: NA | O25: 2500 | P25: 1500 | Q25: 2600 | R25: 3000 | S25: =SUM(G25:R25) -> 9600 | T25: 0 | U25: =S25+T25 -> 9600 | V25: =D25*2 -> 24000 | W25: =U25-V25 -> -14400 | Z25: 0 | AA25: 0 | AC25: 0 | AG25: =SUM(Y25:AF25) -> 0 | AH25: =S25 -> 9600
A26: 25 | B26: Tarekh Shaikh | C26: Salesforce | D26: 6000 | E26: 4000 | F26: Akbar sir | G26: NA | H26: NA | I26: NA | J26: NA | K26: NA | L26: NA | M26: NA | N26: NA | O26: 1000 | P26: 0 | Q26: 1500 | R26: 2000 | S26: =SUM(G26:R26) -> 4500 | T26: 0 | U26: =S26+T26 -> 4500 | V26: =D26*2 -> 12000 | W26: =U26-V26 -> -7500 | Z26: 0 | AA26: 0 | AC26: =O26 -> 1000 | AG26: =SUM(Y26:AF26) -> 1000 | AH26: =W26-AG26 -> -8500
A27: 26 | B27: Zubair Shaikh | C27: E- Commerce | D27: 6000 | E27: 6000 | F27: Akbar sir | G27: NA | H27: NA | I27: NA | J27: NA | K27: NA | L27: NA | M27: NA | N27: NA | O27: NA | P27: 6000 | Q27: 4000 | S27: =SUM(G27:R27) -> 10000 | T27: 0 | U27: =S27+T27 -> 10000 | V27: =D27*2 -> 12000 | W27: =U27-V27 -> -2000 | Z27: 0 | AA27: 0 | AG27: =SUM(Y27:AF27) -> 0 | AH27: =W27-AG27 -> -2000
A28: 27 | B28: Muqtadir Khan | C28: Qliksense | D28: 6000 | E28: 6000 | F28: Akbar sir | G28: NA | H28: NA | I28: NA | J28: NA | K28: NA | L28: NA | M28: NA | N28: NA | O28: NA | P28: 6000 | Q28: 6000 | R28: 6000 | S28: =SUM(G28:R28) -> 18000 | T28: 0 | U28: =S28+T28 -> 18000 | V28: =D28*2 -> 12000 | W28: =U28-V28 -> 6000 | Z28: 0 | AA28: 0 | AF28: =R28 -> 6000 | AG28: =SUM(Y28:AF28) -> 6000 | AH28: =W28-AG28 -> 0
A29: 28 | B29: Adil Khan | C29: Salesforce | D29: 12000 | E29: 4000 | F29: Kaniz Fatema | G29: NA | H29: NA | I29: NA | J29: NA | K29: NA | L29: NA | M29: NA | N29: NA | O29: NA | P29: NA | Q29: 2500 | R29: 2000 | S29: =SUM(G29:R29) -> 4500 | T29: 0 | U29: =S29+T29 -> 4500 | V29: =D29*2 -> 24000 | W29: =U29-V29 -> -19500 | AG29: =SUM(Y29:AF29) -> 0 | AH29: =W29-AG29 -> -19500
A30: 29 | B30: Mohsin Mohd | C30: OIC | D30: 12000 | E30: 8000 | F30: Akbar sir | G30: NA | H30: NA | I30: NA | J30: NA | K30: NA | L30: NA | M30: NA | N30: NA | O30: NA | P30: NA | Q30: 8000 | R30: 8000 | S30: =SUM(G30:R30) -> 16000 | T30: 0 | U30: =S30+T30 -> 16000 | V30: =D30*2 -> 24000 | W30: =U30-V30 -> -8000 | AG30: =SUM(Y30:AF30) -> 0 | AH30: =S30 -> 16000
A31: 30 | B31: Faizan | C31: Salesforce | D31: 20000 | E31: 5000 | F31: kaniz Fatema | G31: NA | H31: NA | I31: NA | J31: NA | K31: NA | L31: NA | M31: NA | N31: NA | O31: NA | P31: NA | Q31: NA | R31: 3000 | S31: =SUM(G31:R31) -> 3000 | T31: 0 | U31: =S31+T31 -> 3000 | V31: =D31*2 -> 40000 | W31: =U31-V31 -> -37000 | AG31: =SUM(Y31:AF31) -> 0 | AH31: =W31-AG31 -> -37000
D32: =SUM(D2:D31) -> 430000 | E32: =SUM(E2:E31) -> 209000 | F32: =SUM(F2:F30) -> 0 | G32: =SUM(G2:G30) -> 45000 | H32: =SUM(H2:H30) -> 42000 | I32: =SUM(I2:I30) -> 48500 | J32: =SUM(J2:J30) -> 52000 | K32: =SUM(K2:K30) -> 52000 | L32: =SUM(L2:L30) -> 57000 | M32: =SUM(M2:M30) -> 91450 | ... Q32: =SUM(Q2:Q30) -> 176600 | R32: =SUM(R2:R31) -> 171000 | S32: =SUM(S2:S30) -> 1074550 | T32: =SUM(T2:T30) -> 352900 | U32: =SUM(U2:U30) -> 1427450 | V32: =SUM(V2:V31) -> 860000 | W32: =SUM(W2:W30) -> 607450 | X32: =SUM(X2:X30) -> 34000 | Y32: =SUM(Y2:Y30) -> 37000 | Z32: =SUM(Z2:Z30) -> 32000 | AA32: =SUM(AA2:AA30) -> 65000 | AB32: =SUM(AB2:AB30) -> 55500 | AC32: =SUM(AC2:AC30) -> 89500 | AD32: =SUM(AD2:AD30) -> 90000 | ... AH32: =SUM(AH2:AH30) -> 132450
D33: Paid with salary
D34: Paid in advance
D35: Paid Total amount
F42: 69500 | G42: 108000
F43: 25000 | G43: =F42+F43-(G42) -> -13500
F44: 40500

Sheet 2021
A1: Sr No | B1: Name of the Employee | C1: Technology | D1: Salary | E1: Bonus amount | F1: Reporting manager | G1: Jan | H1: Feb | I1: Mar | J1: Apr | K1: May | L1: Jun | M1: Jul | N1: Aug | O1: Sep | P1: Oct | Q1: Nov | R1: Dec | S1: This year 2021 bonus amount | T1: Previous year 2020 total bonus amount | U1: Total Bonus Amount | V1: 2 Months salary on hold | W1: Total bonus amount pay after notice period | Y1: To be Paid with Salary in Jan 2021 | Z1: To be Paid with Salary in Feb 2021 | AA1: To be Paid with Salary in Mar 2021 | AB1: To be Paid with Salary in Apr 2021 | AC1: To be Paid with Salary in May 2021 | AD1: To be Paid with Salary in Jun 2021 | AE1: To be Paid with Salary in July 2021 | AF1: To be Paid with Salary in Aug 2021 | AG1: To be Paid with Salary in Sep 2021 | AH1: To be Paid with Salary in Oct 2021 | AI1: To be Paid with Salary in Nov 2021 | AJ1: To be Paid with Salary in Dec 2021 | AK1: Total bonus given in 2021 amount | AL1: Remaining Bonus amount in dec 2021
A2: 1 | B2: Yasmeen | C2: Accountant | D2: 10000 | E2: 5000 | F2: Akbar sir | G2: 3000 | H2: 4000 | I2: 4000 | J2: 4000 | K2: 5000 | L2: 4000 | M2: 3000 | N2: 0 | O2: 4000 | P2: 4000 | Q2: 2000 | R2: 4000 | S2: =SUM(G2:R2) -> 41000 | T2: 0 | U2: 30500 | V2: 20000 | W2: 20000 | Y2: 0 | Z2: 0 | AA2: 0 | AB2: 0 | AC2: 0 | AD2: 4000 | AE2: 3000 | AF2: 0 | AG2: =O2 -> 4000 | AH2: =P2 -> 4000 | AI2: =Q2 -> 2000 | AJ2: =R2 -> 4000 | AK2: =SUM(Y2:AJ2) -> 21000 | AL2: 23500
A3: 2 | B3: Sherkhan Misbah ismail | C3: Accountant | D3: 10000 | E3: 5000 | F3: Akbar sir | G3: NA | H3: NA | I3: NA | J3: NA | K3: NA | L3: NA | M3: NA | N3: NA | O3: 4000 | P3: 5000 | Q3: 4000 | R3: =E3/22*9 -> 2045.4545 | S3: =SUM(G3:R3) -> 15045.455 | AG3: 0 | AH3: 0 | AI3: 0 | AJ3: 0 | AK3: =SUM(Y3:AJ3) -> 0
A4: 3 | B4: Imran | C4: Angular | D4: 12000 | E4: 6000 | F4: Akbar sir | G4: NA | H4: NA | I4: NA | J4: NA | K4: NA | L4: 6000 | M4: 6000 | N4: 6000 | O4: 6000 | P4: 6000 | Q4: 6000 | R4: 6000 | S4: =SUM(G4:R4) -> 42000 | V4: 12000 | AD4: 0 | AE4: 0 | AF4: 6000 | AG4: =O4 -> 6000 | AH4: 0 | AI4: 0 | AJ4: =R4 -> 6000 | AK4: =SUM(Y4:AJ4) -> 18000
A5: 4 | B5: Younus | C5: Angular | D5: 12000 | E5: 4000 | F5: Akbar sir | G5: NA | H5: NA | I5: NA | J5: NA | K5: NA | L5: NA | M5: NA | N5: NA | O5: 4000 | P5: 4000 | Q5: 0 | R5: 4000 | S5: =SUM(G5:R5) -> 12000 | AG5: 0 | AH5: 0 | AI5: 0 | AJ5: 0
A6: 6 | B6: Shaikh Tareq | C6: Dot Net | D6: 25000 | E6: 5000 | F6: Akbar sir | G6: 5000 | H6: 5000 | I6: 5000 | J6: 5000 | K6: 5000 | L6: 5000 | M6: 5000 | N6: 5000 | O6: 5000 | P6: 5000 | Q6: 5000 | R6: =E6/22*7 -> 1590.9091 | S6: =SUM(G6:R6) -> 56590.909 | T6: 0 | U6: 45000 | V6: 50000 | W6: 50000 | Y6: 5000 | Z6: 5000 | AA6: 5000 | AB6: 5000 | AC6: 0 | AD6: 0 | AE6: 5000 | AF6: 5000 | AI6: 0 | AJ6: 0 | AK6: 30000 | AL6: 15000
A7: 7 | B7: Osama | C7: Dot Net | D7: 18000 | E7: 6000 | F7: Akbar sir | G7: NA | H7: 6000 | I7: 6000 | J7: 6000 | K7: 6000 | L7: 6000 | M7: 6000 | N7: 6000 | O7: 6000 | P7: 6000 | Q7: 6000 | R7: =E7/22*7 -> 1909.0909 | S7: =SUM(G7:R7) -> 61909.091 | T7: 0 | U7: =S7+T7 -> 61909.091 | V7: =D7*2 -> 36000 | W7: =U7-V7 -> 25909.091 | Y7: 0 | Z7: 0 | AA7: 0 | AB7: 6000 | AC7: 6000 | AD7: 6000 | AE7: 6000 | AF7: 6000 | AG7: 0 | AH7: 0 | AI7: 0 | AJ7: 10000 | AK7: =SUM(Y7:AJ7) -> 40000 | AL7: =S7-AK7 -> 21909.091
A8: 8 | B8: Salman | C8: Dot Net | D8: 12000 | E8: 6000 | F8: Akbar sir | G8: 6000 | H8: 4000 | I8: 4000 | J8: 6000 | K8: 5000 | L8: 6000 | M8: 6000 | N8: 6000 | O8: 6000 | P8: 6000 | Q8: 6000 | R8: 6000 | S8: =SUM(G8:R8) -> 67000 | T8: 0 | U8: =S8+T8 -> 67000 | V8: =D8*2 -> 24000 | W8: =U8-V8 -> 43000 | Z8: 0 | AA8: 0 | AB8: 6000 | AC8: 5000 | AD8: 6000 | AE8: 6000 | AF8: 6000 | AG8: 0 | AH8: 0 | AI8: =Q8 -> 6000 | AJ8: =R8 -> 6000
A9: 9 | B9: Arshaduddin | C9: Dot Net | D9: 12000 | E9: 6000 | F9: Akbar sir | G9: NA | H9: NA | I9: 3000 | J9: 4000 | K9: 5000 | L9: 6000 | M9: 6000 | N9: 6000 | O9: 6000 | P9: =E9/20*15 -> 4500 | Q9: 6000 | R9: 6000 | S9: =SUM(G9:R9) -> 52500 | T9: 0 | U9: =S9+T9 -> 52500 | V9: =D9*2 -> 24000 | W9: =U9-V9 -> 28500 | Z9: 0 | AA9: 0 | AB9: 0 | AC9: 0 | AD9: 6000 | AE9: 6000 | AF9: 6000 | AG9: 0 | AH9: 0 | AI9: 0 | AJ9: 6000
A10: 10 | B10: Nagma Khan | C10: Dot Net | D10: 17000 | E10: 10000 | F10: Akbar sir | G10: 10000 | H10: 10000 | I10: 4000 | J10: 0 | K10: 0 | L10: 0 | M10: 0 | N10: 0 | O10: =E10/23*11 -> 4782.6087 | P10: =E10/21*6 -> 2857.1429 | Q10: 10000 | R10: 10000 | S10: 29000 | T10: -6000 | U10: 23000 | V10: 34000 | W10: 28000 | Y10: 10000 | Z10: 10000 | AA10: 4000 | AB10: 0 | AC10: 0 | AD10: 0 | AH10: =P10 -> 2857.1429 | AI10: =Q10 -> 10000 | AJ10: =R10 -> 10000 | AK10: 24000 | AL10: -1000
A11: 11 | B11: Muzafar | C11: Dot Net | D11: 12000 | E11: 6000 | F11: Akbar sir | G11: NA | H11: NA | I11: NA | J11: 6000 | K11: 6000 | L11: 6000 | M11: 6000 | N11: 6000 | O11: 6000 | P11: 6000 | Q11: 6000 | R11: 6000 | S11: =SUM(G11:R11) -> 54000 | U11: 0 | V11: 24000 | AB11: 0 | AC11: 0 | AD11: 0 | AE11: 0 | AF11: 6000 | AG11: =O11 -> 6000 | AH11: =P11 -> 6000 | AI11: =Q11 -> 6000 | AJ11: =R11 -> 6000
A12: 12 | B12: Shaikh Mudassir | C12: E-automate | D12: 18000 | E12: 6000 | F12: Akbar sir | G12: 6000 | H12: 6000 | I12: 6000 | J12: 6000 | K12: 5000 | L12: 5000 | M12: 5000 | N12: 6000 | O12: 6000 | P12: 6000 | Q12: 6000 | R12: 6000 | S12: =SUM(G12:R12) -> 69000 | T12: 10650 | U12: =S12+T12 -> 79650 | V12: =D12*2 -> 36000 | W12: =U12-V12 -> 43650 | Y12: 6000 | Z12: 0 | AA12: 6000 | AB12: 6000 | AC12: 0 | AD12: 0 | AE12: 5000 | AF12: 6000 | AG12: =O12 -> 6000 | AH12: =P12 -> 6000 | AI12: =Q12 -> 6000 | AJ12: =R12 -> 6000 | AK12: =SUM(Y12:AJ12) -> 53000 | AL12: =S12-AK12 -> 16000
A13: 13 | B13: Shaikh Javed | C13: E-automate | D13: 12000 | E13: 6000 | F13: Akbar sir | G13: 6000 | H13: 6000 | I13: 6000 | J13: 6000 | K13: 5000 | L13: 5000 | M13: 5000 | N13: 6000 | O13: 6000 | P13: 6000 | Q13: 6000 | R13: 6000 | S13: =SUM(G13:R13) -> 69000 | T13: 0 | U13: 51000 | V13: 24000 | W13: 24000 | Y13: 6000 | Z13: 0 | AA13: 6000 | AB13: 6000 | AC13: 0 | AD13: 0 | AE13: 5000 | AF13: 6000 | AG13: =O13 -> 6000 | AH13: =P13 -> 6000 | AI13: =Q13 -> 6000 | AJ13: =R13 -> 6000 | AK13: =SUM(Y13:AJ13) -> 53000 | AL13: =S13-AK13 -> 16000
A14: 14 | B14: Noorul Khan | C14: E-automate | D14: 6000 | E14: 6000 | F14: Akbar sir | G14: NA | H14: NA | I14: NA | J14: NA | K14: 6000 | L14: 6000 | M14: 6000 | N14: 6000 | O14: 6000 | P14: 6000 | Q14: 6000 | R14: 6000 | S14: =SUM(G14:R14) -> 48000 | T14: 0 | U14: =S14+T14 -> 48000 | V14: 12000 | W14: =U14-V14 -> 36000 | AC14: 0 | AD14: 0 | AE14: 6000 | AF14: 6000 | AG14: =O14 -> 6000 | AH14: =P14 -> 6000 | AI14: =Q14 -> 6000 | AJ14: =R14 -> 6000 | AK14: 12000 | AL14: -12000
A15: 15 | B15: Shazeena | C15: Financial Force | D15: 16000 | E15: 6000 | F15: Akbar sir | G15: 6000 | H15: 6000 | I15: 6000 | J15: 5000 | K15: 6000 | L15: 6000 | M15: 6000 | N15: 6000 | O15: 6000 | P15: 6000 | Q15: 6000 | R15: 6000 | S15: =SUM(G15:R15) -> 71000 | T15: 0 | U15: =S15+T15 -> 71000 | V15: =D15*2 -> 32000 | W15: =U15-V15 -> 39000 | Y15: 0 | Z15: 0 | AA15: 6000 | AB15: 5000 | AC15: 6000 | AD15: 0 | AE15: 0 | AF15: 0 | AG15: 0 | AH15: =P15 -> 6000 | AI15: =Q15 -> 6000 | AJ15: =R15 -> 6000 | AK15: 17000 | AL15: 36000
A16: 17 | B16: Amir Dalvi | C16: Financial Force | D16: 12000 | E16: 4000 | F16: Akbar sir | G16: NA | H16: NA | I16: NA | J16: NA | K16: NA | L16: NA | M16: NA | N16: NA | O16: 4000 | P16: 4000 | Q16: 4000 | R16: 4000 | AG16: 0 | AH16: 0 | AI16: 0 | AJ16: 0
A17: 18 | B17: Maaz Shaokat Choughle | C17: Financial Force | D17: 30000 | E17: 5000 | F17: Akbar sir | G17: 4000 | H17: 3000 | I17: 3000 | J17: 7000 | K17: 10000 | L17: 10000 | M17: 8000 | N17: 8000 | O17: 5000 | P17: 5000 | Q17: 5000 | R17: =E17/22*13 -> 2954.5455 | S17: 58000 | T17: #REF! | U17: ####### | V17: 60000 | W17: ####### | Y17: 0 | Z17: 0 | AA17: 0 | AB17: 7000 | AD17: 10000 | AE17: 8000 | AF17: 8000 | AG17: 0 | AH17: 0 | AI17: 0 | AJ17: 0
A18: 19 | B18: Najeeb | C18: Financial Force | D18: 20000 | E18: 5000 | F18: Akbar sir | G18: NA | H18: NA | I18: NA | J18: 4000 | K18: 4000 | L18: 4000 | M18: 4000 | N18: 3000 | O18: 4000 | P18: =E18/20*5 -> 1250 | Q18: 5000 | R18: 4000 | S18: =SUM(G18:R18) -> 33250 | T18: 0 | U18: =S18+T18 -> 33250 | V18: =D18*2 -> 40000 | AB18: 0 | AD18: 0 | AF18: 0 | AG18: 0 | AH18: 0 | AI18: 0 | AJ18: 0
A19: 20 | B19: Nabeela khan | C19: Microsoft CRM | D19: 40000 | E19: 10000 | F19: Akbar sir | G19: 10000 | H19: 10000 | I19: 10000 | J19: 10000 | K19: 10000 | L19: 10000 | M19: 7000 | N19: 10000 | O19: 10000 | P19: 10000 | Q19: =E19/23*13 -> 5652.1739 | R19: 10000 | S19: 87000 | T19: 0 | U19: 87000 | V19: 80000 | W19: 80000 | Y19: 10000 | Z19: 10000 | AA19: 10000 | AB19: 10000 | AC19: 10000 | AD19: 8250 | AE19: 7000 | AF19: 10000 | AG19: =O19 -> 10000 | AH19: =P19 -> 10000 | AJ19: =R19 -> 10000 | AK19: 75250 | AL19: 11750
A20: 21 | B20: Irfan Shaikh | C20: Microsoft CRM | D20: 25000 | E20: 5000 | F20: Akbar sir | G20: 6000 | H20: 6000 | I20: 6000 | J20: 4000 | K20: 6000 | L20: 6000 | M20: 4000 | N20: 6000 | O20: 6000 | P20: 0 | Q20: 3000 | R20: =G20/22*7 -> 1909.0909 | S20: 50000 | T20: 0 | U20: 50000 | V20: 28000 | W20: 28000 | Y20: 6000 | Z20: 6000 | AA20: 6000 | AB20: 4000 | AC20: 0 | AD20: 0 | AE20: 0 | AF20: 0 | AG20: =O20 -> 6000 | AH20: 0 | AJ20: 0 | AK20: 22000 | AL20: 28000
A21: 22 | B21: Neha Shaikh | C21: Microsoft CRM | D21: 12000 | E21: 4000 | F21: Akbar sir | G21: NA | H21: NA | I21: NA | J21: NA | K21: NA | L21: NA | M21: NA | N21: NA | O21: 4000 | P21: 4000 | Q21: =E21/23*20 -> 3478.2609 | R21: 4000 | S21: =SUM(H21:R21) -> 15478.261 | AG21: 0 | AH21: 0 | AJ21: 0 | AL21: =S21 -> 15478.261
A22: 23 | B22: Mohsin Mohd | C22: OIC | D22: 25000 | E22: 5000 | F22: Akbar sir | G22: 8000 | H22: 8000 | I22: 8000 | J22: 8000 | K22: 8000 | L22: 5000 | M22: 5000 | N22: 5000 | O22: 5000 | P22: 5000 | Q22: 5000 | R22: 5000 | S22: =SUM(G22:R22) -> 75000 | T22: 0 | U22: 60000 | V22: 50000 | W22: 50000 | Y22: 0 | Z22: 8000 | AA22: 8000 | AB22: 8000 | AC22: 8000 | AD22: 5000 | AE22: 5000 | AF22: 5000 | AG22: 0 | AH22: 0 | AJ22: 0 | AK22: 47000 | AL22: =S22-AK22 -> 28000
A23: 24 | B23: Shamshad Ahmed | C23: Qliksense | D23: 22000 | E23: 8000 | F23: Akbar sir | G23: 8000 | H23: 8000 | I23: 8000 | J23: 8000 | K23: 8000 | L23: 8000 | M23: 8000 | N23: 8000 | O23: 8000 | P23: =E23/20*15 -> 6000 | Q23: =E23/23*18 -> 6260.8696 | R23: 8000 | S23: 72000 | T23: 0 | U23: 72000 | V23: 44000 | W23: 44000 | Y23: 8000 | Z23: 8000 | AA23: 8000 | AB23: 8000 | AC23: 0 | AD23: 0 | AE23: 0 | AF23: 8000 | AG23: =O23 -> 8000 | AH23: =P23 -> 6000 | AI23: =Q23 -> 6260.8696 | AJ23: =R23 -> 8000 | AK23: 40000 | AL23: 32000
A24: 25 | B24: Ahtesham | C24: Qliksense | D24: 6000 | E24: 6000 | F24: Akbar sir | G24: NA | H24: NA | I24: 6000 | J24: 6000 | K24: 5000 | L24: 6000 | M24: 6000 | N24: 6000 | O24: 6000 | P24: 6000 | Q24: 6000 | R24: 6000 | S24: =SUM(G24:R24) -> 59000 | U24: 41000 | V24: 12000 | W24: 12000 | Y24: NA | Z24: 0 | AA24: 0 | AB24: 0 | AC24: 5000 | AD24: 6000 | AE24: 6000 | AF24: 6000 | AG24: =O24 -> 6000 | AH24: =P24 -> 6000 | AI24: =Q24 -> 6000 | AJ24: =R24 -> 6000 | AK24: =SUM(AC24:AJ24) -> 47000 | AL24: =S24-AK24 -> 12000
A25: 26 | B25: Tauseef | C25: Qliksense | D25: 14000 | E25: 6000 | F25: Akbar sir | G25: NA | H25: NA | I25: NA | J25: NA | K25: NA | L25: NA | M25: 6000 | N25: 6000 | O25: 6000 | P25: 6000 | Q25: 6000 | R25: 6000 | S25: =SUM(L25:R25) -> 36000 | V25: 12000 | AE25: 0 | AF25: 0 | AG25: =O25 -> 6000 | AH25: =P25 -> 6000 | AI25: =Q25 -> 6000 | AJ25: 0 | AK25: =SUM(Y25:AJ25) -> 18000 | AL25: =S25-AK25 -> 18000
A26: 27 | B26: Warfan | C26: Qliksense | D26: 14000 | E26: 6000 | F26: Akbar sir | G26: NA | H26: NA | I26: NA | J26: NA | K26: NA | L26: NA | M26: 6000 | N26: 6000 | O26: 6000 | P26: 6000 | Q26: 5000 | R26: 6000 | S26: =SUM(G26:R26) -> 35000 | T26: 0 | U26: =S26+T26 -> 35000 | V26: =D26*2 -> 28000 | W26: =U26-V26 -> 7000 | AE26: 0 | AF26: 0 | AG26: =O26 -> 6000 | AH26: 0 | AJ26: 6000 | AK26: 0 | AL26: 0
A27: 28 | B27: Fahmida | C27: Sales | D27: 10000 | E27: 5000 | F27: Akbar sir | G27: NA | H27: NA | I27: NA | J27: NA | K27: NA | L27: NA | M27: 5000 | N27: 5000 | O27: 5000 | P27: 5000 | Q27: =E27/23*20 -> 4347.8261 | R27: =E27/22*10 -> 2272.7273 | V27: 20000 | W27: 20000 | AE27: 0 | AF27: 0 | AG27: 0 | AH27: 0 | AI27: =Q27 -> 4347.8261 | AJ27: =R27 -> 2272.7273 | AK27: 0 | AL27: 0
A28: 29 | B28: Ibrahim | C28: Sales | D28: 18000 | E28: 7000 | F28: Akbar sir | G28: 7000 | H28: 7000 | I28: 7000 | J28: 7000 | K28: 7000 | L28: 7000 | M28: 7000 | N28: 7000 | O28: 7000 | P28: 0 | Q28: =E28/23*14 -> 4260.8696 | R28: 7000 | S28: 63000 | U28: 63000 | V28: 36000 | W28: 36000 | Y28: 7000 | Z28: 7000 | AA28: 7000 | AB28: 7000 | AC28: 7000 | AD28: 7000 | AE28: 7000 | AF28: 7000 | AG28: =O28 -> 7000 | AH28: =P28 -> 0 | AI28: =Q28 -> 4260.8696 | AJ28: =R28 -> 7000 | AK28: 56000 | AL28: 7000
A29: 30 | B29: Sana | C29: Sales | D29: 10000 | E29: 5000 | F29: Akbar sir | G29: NA | H29: NA | I29: NA | J29: NA | K29: NA | L29: NA | M29: NA | N29: NA | O29: NA | P29: 5000 | Q29: =E29-2000 -> 3000 | R29: =E29/22*12 -> 2727.2727 | S29: =SUM(P29:R29) -> 10727.273 | AH29: 0 | AL29: =S29 -> 10727.273
A30: 31 | B30: Mohammad Rehanuddin | C30: Salesforce | D30: 47000 | E30: 5000 | F30: Akbar sir | G30: 5000 | H30: 10000 | I30: 10000 | J30: 10000 | K30: 10000 | L30: 10000 | M30: 10000 | N30: 10000 | O30: 10000 | P30: 10000 | Q30: 5000 | R30: 5000 | S30: 85000 | T30: 0 | U30: 85000 | V30: 70000 | W30: 70000 | Y30: 5000 | Z30: 10000 | AA30: 10000 | AB30: 10000 | AC30: 0 | AD30: 10000 | AE30: 10000 | AF30: 10000 | AG30: 0 | AH30: =P30 -> 10000 | AI30: =Q30 -> 5000
A31: 33 | B31: Gaus | C31: Salesforce | D31: 15000 | E31: 10000 | F31: Akbar sir | G31: NA | H31: NA | I31: NA | J31: NA | K31: 3000 | L31: 8000 | M31: 8500 | N31: 5000 | O31: 10000 | P31: 10000 | Q31: 10000 | R31: 8000 | V31: 30000 | AD31: 0 | AF31: 0 | AG31: 0 | AH31: =P31 -> 10000 | AI31: =Q31 -> 10000 | AJ31: =R31 -> 8000
A32: 34 | B32: Zafar | C32: Salesforce | D32: 12000 | E32: 4000 | F32: Akbar sir | G32: NA | H32: NA | I32: NA | J32: NA | K32: NA | L32: NA | M32: NA | N32: NA | O32: 4000 | P32: 3000 | Q32: 4000 | R32: 2000 | AG32: 0 | AH32: 0 | AJ32: 0
A33: 35 | B33: Shahzad | C33: Salesforce | D33: 12000 | E33: 4000 | F33: Akbar sir | G33: NA | H33: NA | I33: NA | J33: NA | K33: NA | L33: 4000 | M33: 4000 | N33: 4000 | O33: 4000 | P33: 3000 | Q33: 2000 | R33: 4000 | V33: 24000 | AD33: 0 | AE33: 0 | AF33: 0 | AG33: 0 | AH33: 0 | AJ33: 0 | AK33: 0 | AL33: 0
A34: 36 | B34: Mustaqeem | C34: Salesforce | D34: 25000 | E34: 10000 | F34: Akbar sir | G34: 3000 | H34: 5000 | I34: 5000 | J34: 5000 | K34: 10000 | L34: 10000 | M34: 10000 | N34: 10000 | O34: 10000 | P34: 10000 | Q34: 10000 | R34: =E34/22*7 -> 3181.8182 | S34: 68000 | T34: 0 | U34: 68000 | V34: 50000 | W34: 50000 | Y34: 0 | Z34: 5000 | AA34: 5000 | AB34: 5000 | AC34: 0 | AD34: 10000 | AE34: 10000 | AF34: 10000 | AG34: =O34 -> 10000 | AH34: =P34 -> 10000 | AI34: =Q34 -> 10000 | AJ34: =R34 -> 3181.8182
A35: 38 | B35: Saba Shaikh | C35: SharePoint | D35: 30000 | E35: 10000 | F35: Akbar sir | G35: 10000 | H35: 5000 | I35: 9000 | J35: 10000 | K35: 9000 | L35: 10000 | M35: 10000 | N35: 10000 | O35: =E35/23*19 -> 8260.8696 | P35: 10000 | Q35: 10000 | R35: 10000 | S35: =SUM(G35:R35) -> 111260.87 | T35: 22000 | U35: =S35+T35 -> 133260.87 | V35: 60000 | W35: =U35-V35 -> 73260.87 | Y35: 10000 | Z35: 5000 | AA35: 9000 | AB35: 0 | AC35: 0 | AD35: 10000 | AE35: 10000 | AF35: 10000 | AG35: 0 | AH35: =P35 -> 10000 | AI35: =Q35 -> 10000 | AJ35: =R35 -> 10000 | AK35: =SUM(Y35:AJ35) -> 84000 | AL35: =AK35-W35 -> 10739.13
A36: 40 | B36: Rahmath | C36: SharePoint | D36: 12000 | E36: 4000 | F36: Akbar sir | G36: NA | H36: NA | I36: NA | J36: NA | K36: NA | L36: NA | M36: 4000 | N36: 4000 | O36: 4000 | P36: 4000 | Q36: 4000 | R36: 4000 | V36: 24000 | AE36: 0 | AF36: 0 | AG36: 0 | AH36: 0 | AJ36: 0
A37: 42 | B37: Khizer | C37: Uipath | D37: 6000 | E37: 6000 | F37: Akbar sir | G37: NA | H37: 6000 | I37: 3000 | J37: 6000 | K37: 6000 | L37: 6000 | M37: 6000 | N37: 15062 | O37: 15250 | P37: 17250 | Q37: 6000 | R37: 6000 | S37: =SUM(G37:R37) -> 92562 | U37: 48062 | V37: 12000 | Z37: 0 | AA37: 0 | AB37: 0 | AC37: 6000 | AD37: 6000 | AE37: 6000 | AF37: 18000 | AG37: =O37 -> 15250 | AH37: =P37 -> 17250 | AI37: =Q37 -> 6000 | AJ37: =R37 -> 6000 | AK37: =SUM(Y37:AJ37) -> 80500 | AL37: =S37-AK37 -> 12062
A38: 43 | B38: Rameez | C38: Uipath | D38: 6000 | E38: 6000 | F38: Akbar sir | G38: NA | H38: NA | I38: NA | J38: NA | K38: NA | L38: 6000 | M38: 6000 | N38: 16571 | O38: 17250 | P38: 17250 | Q38: 6000 | R38: 6000 | S38: =SUM(G38:R38) -> 75071 | V38: 12000 | AD38: 0 | AE38: 0 | AF38: 20000 | AG38: =O38 -> 17250 | AH38: =P38 -> 17250 | AI38: =Q38 -> 6000 | AJ38: =R38 -> 6000 | AK38: =SUM(AD38:AJ38) -> 66500 | AL38: =S38-AK38 -> 8571
A39: 47 | B39: Ahad | C39: wordpresss | D39: 10000 | E39: 6000 | F39: Akbar sir | G39: NA | H39: NA | I39: NA | J39: NA | K39: NA | L39: NA | M39: NA | N39: NA | O39: NA | P39: 6000 | Q39: 0 | R39: 0 | AH39: 0 | AJ39: =R39 -> 0
A40: 48 | B40: Amir Shaikh | C40: wordpresss | D40: 6000 | E40: 6000 | F40: Akbar sir | G40: NA | H40: NA | I40: NA | J40: NA | K40: NA | L40: NA | M40: NA | N40: NA | O40: 6000 | P40: 6000 | Q40: 6000 | R40: 6000 | S40: =SUM(O40:R40) -> 24000 | AG40: 0 | AH40: 0 | AI40: 6000 | AJ40: =R40 -> 6000 | AK40: =SUM(AG40:AJ40) -> 12000 | AL40: =S40-AK40 -> 12000
...

Sheet 2022
A1: Sr No | B1: Name of the Employee | C1: Technology | D1: Salary | E1: Bonus amount | F1: Reporting manager | G1: Jan | H1: Feb | I1: Mar | J1: Apr | K1: May | L1: Jun | M1: Jul | N1: Aug | O1: Sep | P1: Oct | Q1: Nov | R1: Dec | S1: This year 2022 bonus amount | T1: as per rule 2 month hold bonus amount should be | U1: Deposit bonus Amount along with us till 2022 paid after notice period /Contract | V1: Hold Bonus paid amount 2022 | W1: To be Paid with Salary in Jan 2022 | X1: To be Paid with Salary in Feb 2022 | Y1: To be Paid with Salary in Mar 2022 | Z1: To be Paid with Salary in Apr 2022 | AA1: To be Paid with Salary in May 2022 | AB1: To be Paid with Salary in Jun 2022 | AC1: To be Paid with Salary in July 2022 | AD1: To be Paid with Salary in Aug 2022 | AE1: To be Paid with Salary in Sep 2022 | AF1: To be Paid with Salary in Oct 2022 | AG1: To be Paid with Salary in Nov 2022 | AH1: To be Paid with Salary in Dec 2022 | AJ1: Total bonus given in 2022 amount | AK1: remaining 2022 | AL1: remaining 2021 | AM1: remaining 2020 | AN1: Total Balance need to pay after notice period
A2: 1 | B2: Ansari Yasmeen | C2: Accounts | D2: 10000 | E2: 8000 | F2: Akbar sir | G2: 5000 | H2: 4000 | I2: 5000 | J2: 5000 | K2: 5000 | L2: =E2/23*14 -> 4869.5652 | M2: 4000 | N2: 5000 | O2: 11000 | P2: 8000 | Q2: =8000/23*18 -> 6260.8696 | R2: 6000 | S2: =SUM(G2:R2) -> 69130.435 | T2: =D2*2 -> 20000 | U2: ='2021'!S2-'2021'!AK2 -> 20000 | V2: =0 -> 0 | W2: =G2 -> 5000 | X2: =H2 -> 4000 | Y2: =I2 -> 5000 | Z2: =J2 -> 5000 | AA2: =K2 -> 5000 | AB2: =L2 -> 4869.5652 | AC2: 4000 | AD2: =N2 -> 5000 | AE2: =O2 -> 11000 | AF2: =P2 -> 8000 | AG2: =Q2 -> 6260.8696 | AH2: =R2 -> 6000 | AI2: a | AJ2: =SUM(W2:AH2) -> 69130.435 | AK2: =S2-W2-X2-Y2-Z2-AA2-AB2-AC2-AD2-AE2-AF2-AG2-AH2 -> 7.2759576e-12 | AL2: ='2021'!S2-'2021'!AD2-'2021'!AE2-'2021'!AF2-'2021'!AG2-'2021'!AH2-'2021'!AI2-'2021'!AJ2 -> 20000 | AN2: =AK2+AL2 -> 20000
A3: 2 | B3: Sherkhan Misbah ismail | C3: Accounts | D3: 10000 | E3: 8000 | F3: Akbar sir | G3: 5000 | H3: 4500 | I3: 5000 | J3: 5000 | K3: 5000 | L3: 5000 | M3: 5000 | N3: 5000 | O3: =E3/22*17 -> 6181.8182 | P3: 8000 | Q3: 8000 | R3: =E3/22*18 -> 6545.4545 | S3: =SUM(G3:R3) -> 68227.273 | T3: =D3*2 -> 20000 | U3: ='2021'!S3+'2022'!G3 -> 20045.455 | V3: =0 -> 0 | W3: 0 | X3: =H3 -> 4500 | Y3: =I3 -> 5000 | Z3: =J3 -> 5000 | AA3: =K3 -> 5000 | AB3: =L3 -> 5000 | AC3: 5000 | AD3: =N3 -> 5000 | AE3: =O3 -> 6181.8182 | AF3: =P3 -> 8000 | AG3: =Q3 -> 8000 | AH3: =R3 -> 6545.4545 | AI3: a | AJ3: =SUM(W3:AH3) -> 63227.273 | AK3: =S3-W3-X3-Y3-Z3-AA3-AB3-AC3-AD3-AE3-AF3-AG3-AH3 -> 5000 | AL3: ='2021'!S3-'2021'!AK3 -> 15045.455 | AN3: =AK3+AL3 -> 20045.455
A4: 3 | B4: Imran Ahmed | C4: Angular | D4: 25000 | E4: 5000 | F4: Akbar sir | G4: 6000 | H4: 6000 | I4: 6000 | J4: =I4 -> 6000 | K4: 6000 | L4: 6000 | M4: 6000 | N4: 4000 | O4: 0 | P4: 5000 | Q4: 5000 | R4: =E4/21*18 -> 4285.7143 | S4: =SUM(G4:R4) -> 60285.714 | T4: =D4*2 -> 50000 | U4: 0 | V4: ='Hold bonus paid sheet'!C11 -> 66000 | W4: =G4 -> 6000 | X4: =H4 -> 6000 | Y4: =I4 -> 6000 | Z4: =J4 -> 6000 | AA4: =K4 -> 6000 | AB4: =L4 -> 6000 | AC4: 6000 | AD4: =N4 -> 4000 | AE4: =O4 -> 0 | AF4: =P4 -> 5000 | AG4: =Q4 -> 5000 | AH4: =R4 -> 4285.7143 | AI4: a | AJ4: =SUM(W4:AH4) -> 60285.714 | AK4: =S4-AJ4+SUM('To beDeleted'!I55:S55) -> 42000 | AL4: ='2021'!S4-'2021'!AF4-'2021'!AG4-'2021'!AH4-'2021'!AI4-'2021'!AJ4 -> 24000 | AN4: =AK4+AL4-V4 -> 0
A5: 4 | B5: Shaikh Muddassir | C5: Angular | D5: 18000 | E5: 6000 | F5: Akbar sir | G5: 6000 | H5: 6000 | I5: 6000 | J5: 3000 | K5: 3000 | L5: 3000 | M5: 3000 | N5: 3000 | O5: 0 | P5: 3000 | Q5: 0 | R5: =E5/21*10 -> 2857.1429 | S5: =SUM(G5:R5) -> 38857.143 | T5: =D5*2 -> 36000 | U5: ='2020'!AH20+'2021'!AL12+'2022'!G5+'2022'!I5+'2022'!L5 -> 44650 | V5: =0 -> 0 | W5: 0 | X5: =H5 -> 6000 | Y5: 0 | Z5: =J5 -> 3000 | AA5: =K5 -> 3000 | AB5: 0 | AC5: 3000 | AD5: =N5 -> 3000 | AE5: =O5 -> 0 | AF5: =P5 -> 3000 | AG5: =Q5 -> 0 | AH5: =R5 -> 2857.1429 | AI5: a | AJ5: =SUM(W5:AH5) -> 23857.143 | AK5: =S5-AJ5 -> 15000 | AL5: ='2021'!S12-'2021'!AK12 -> 16000 | AM5: ='2020'!S20-'2020'!AG20 -> 13650 | AN5: =AK5+AL5+AM5-V5 -> 44650
A6: 5 | B6: Shaikh Tareque | C6: Angular | D6: 40000 | E6: 10000 | F6: Akbar sir | G6: 5000 | H6: 5000 | I6: 5000 | J6: =I6 -> 5000 | K6: =J6 -> 5000 | L6: 5000 | M6: 5000 | N6: 3000 | O6: 3000 | P6: =E6/21*16 -> 7619.0476 | Q6: 0 | R6: 0 | S6: =SUM(G6:R6) -> 48619.048 | T6: =D6*2 -> 80000 | U6: =SUM(O6:R6) -> 10619.048 | V6: ='Hold bonus paid sheet'!C7 -> 54090 | W6: 0 | X6: =H6 -> 5000 | Y6: =I6 -> 5000 | Z6: =J6 -> 5000 | AA6: =K6 -> 5000 | AB6: =L6 -> 5000 | AC6: 5000 | AD6: =N6 -> 3000 | AE6: 0 | AF6: 0 | AG6: 0 | AH6: 0 | AJ6: =SUM(W6:AH6) -> 33000 | AK6: =S6-AJ6 -> 15619.048 | AL6: ='2021'!S6-'2021'!AK6 -> 26590.909 | AM6: ='2020'!S15-'2020'!AG15 -> 12000
A7: 6 | B7: Khan Noorul Hasan | C7: E-automate | D7: 30000 | E7: 5000 | F7: Akbar sir | G7: 6000 | H7: 6000 | I7: 6000 | J7: =I7 -> 6000 | K7: =J7 -> 6000 | L7: 6000 | M7: 6000 | N7: =6000/23*10 -> 2608.6957 | O7: 5000 | P7: 5000 | Q7: =5000/23*19 -> 4130.4348 | R7: 0 | S7: =SUM(G7:R7) -> 58739.13 | T7: =D7*2 -> 60000 | U7: =SUM(O7:R7) -> 14130.435 | V7: =0 -> 0 | W7: 0 | X7: 0 | Y7: =I7 -> 6000 | Z7: =J7 -> 6000 | AA7: =K7 -> 6000 | AB7: =L7 -> 6000 | AC7: 6000 | AD7: =N7 -> 2608.6957 | AE7: 0 | AF7: 0 | AG7: 0 | AH7: 0 | AJ7: =SUM(W7:AH7) -> 32608.696
A8: 7 | B8: Shaikh Javed | C8: Microsoft CRM | D8: 12000 | E8: 6000 | F8: Akbar sir | G8: 6000 | H8: 6000 | I8: 6000 | J8: =I8 -> 6000 | K8: =J8 -> 6000 | L8: 3000 | M8: 3000 | N8: 3000 | O8: 0 | P8: 6000 | Q8: 6000 | R8: 6000 | S8: =SUM(G8:R8) -> 57000 | T8: =D8*2 -> 24000 | U8: ='2020'!AH21+'2021'!AL13+'2022'!M9 -> 35800 | V8: =0 -> 0 | W8: =G8 -> 6000 | X8: =H8 -> 6000 | Y8: =I8 -> 6000 | Z8: =J8 -> 6000 | AA8: =K8 -> 6000 | AB8: =L8 -> 3000 | AC8: 0 | AD8: =N8 -> 3000 | AE8: =O8 -> 0 | AF8: =P8 -> 6000 | AG8: =Q8 -> 6000 | AH8: =R8 -> 6000 | AI8: a | AJ8: =SUM(W8:AH8) -> 54000
A9: 8 | B9: Osama Khan | C9: Microsoft CRM | D9: 35000 | E9: 5000 | F9: Akbar sir | G9: 6000 | H9: 6000 | I9: =E9/20*14 -> 3500 | J9: 6000 | K9: 6000 | L9: 6000 | M9: 6000 | N9: =E9/23*16 -> 3478.2609 | O9: 6000 | P9: =6000/21*11+5000/21*10-3142.86 -> 2380.9495 | Q9: 0 | R9: 5000 | S9: =SUM(P9:R9) -> 7380.9495 | T9: =D9*2 -> 70000 | U9: =SUM(P9:R9) -> 7380.9495 | V9: ='Hold bonus paid sheet'!C9 -> 37909 | W9: 0 | X9: =H9 -> 6000 | Y9: 4200 | Z9: =J9 -> 6000 | AA9: =K9 -> 6000 | AB9: =L9 -> 6000 | AC9: 6000 | AD9: 4174 | AE9: =O9 -> 6000 | AF9: =6000/21*11 -> 3142.8571 | AG9: 0 | AH9: 0 | AJ9: =SUM(W9:AH9) -> 47516.857
A10: 9 | B10: Amir Khan | C10: Microsoft CRM | D10: 10000 | E10: 10000 | F10: Akbar sir | G10: NA | H10: NA | I10: NA | J10: NA | K10: NA | L10: NA | M10: NA | N10: NA | O10: =E10/22*9 -> 4090.9091 | P10: 10000 | Q10: 5000 | R10: 10000 | S10: =SUM(G10:R10) -> 29090.909 | T10: =D10*2 -> 20000 | U10: =SUM(O10:R10) -> 29090.909 | V10: 0 | AE10: 0 | AF10: 0 | AG10: 0 | AH10: 0 | AJ10: =SUM(W10:AH10) -> 0
A11: 10 | B11: Mohsin Mohd | C11: OIC | D11: 50000 | E11: 10000 | F11: Akbar sir | G11: 5000 | H11: 3478 | I11: 5000 | J11: =I11 -> 5000 | K11: 5000 | L11: 10000 | M11: 10000 | N11: 10000 | O11: 10000 | P11: =E11/21*10 -> 4761.9048 | Q11: 10000 | R11: =E11/21*16 -> 7619.0476 | S11: =SUM(G11:R11) -> 85858.952 | T11: =D11*2 -> 100000 | U11: =SUM(L11:R11) -> 62380.952 | V11: 0 | W11: 0 | X11: 0 | Y11: 0 | Z11: =J11 -> 5000 | AA11: 5000 | AB11: 0 | AC11: 0 | AD11: 0 | AE11: 0 | AF11: 0 | AG11: 0 | AH11: 0 | AJ11: =SUM(W11:AH11) -> 10000
A12: 11 | B12: Arshad Ansari | C12: OIC | D12: 6000 | E12: 10000 | F12: Akbar sir | G12: NA | H12: 10000 | I12: 10000 | J12: 10000 | K12: 10000 | L12: 10000 | M12: 10000 | N12: 10000 | O12: 10000 | P12: 10000 | Q12: =10000/23*13 -> 5652.1739 | R12: 8000 | S12: =SUM(G12:R12) -> 103652.17 | T12: =D12*2 -> 12000 | U12: =SUM(H12:R12) -> 103652.17 | V12: 0 | W12: 0 | X12: 0 | Y12: 0 | Z12: 0 | AA12: 0 | AB12: 0 | AC12: 0 | AD12: 0 | AE12: 0 | AF12: 0 | AG12: 0 | AH12: 0 | AJ12: =SUM(W12:AH12) -> 0
A13: 12 | B13: Ziaullah Ansari | C13: OIC | D13: 6000 | E13: 10000 | F13: Akbar sir | G13: NA | H13: NA | I13: NA | J13: NA | K13: NA | L13: NA | M13: NA | N13: NA | O13: NA | P13: NA | Q13: 10000 | R13: 10000 | T13: =D13*2 -> 12000 | AG13: 4000 | AH13: 4000 | AI13: a | AJ13: =SUM(W13:AH13) -> 8000
A14: 13 | B14: Tauseef Khan | C14: Qlik sense | D14: 30000 | E14: 10000 | F14: Akbar sir | G14: 6000 | H14: =E14/23*13 -> 5652.1739 | I14: 6000 | J14: 10000 | K14: 10000 | L14: 2000 | M14: 5000 | N14: 5000 | O14: 7000 | P14: 5000 | Q14: 5000 | R14: 0 | S14: =SUM(G14:R14) -> 66652.174 | T14: =D14*2 -> 60000 | U14: ='2021'!AL25+'2022'!G14+'2022'!H14+SUM(J14:R14) -> 78652.174 | V14: 0 | W14: 0 | X14: 0 | Y14: =I14 -> 6000 | Z14: 0 | AA14: 0 | AB14: 0 | AC14: 0 | AD14: 0 | AE14: 0 | AF14: 0 | AG14: 0 | AH14: 0 | AJ14: =SUM(W14:AH14) -> 6000
A15: 14 | B15: Syed Mustafa | C15: Qlik Sense | D15: 6000 | E15: 10000 | F15: Akbar sir | G15: NA | H15: NA | I15: NA | J15: NA | K15: =E15/22*22 -> 10000 | L15: 10000 | M15: 10000 | N15: 10000 | O15: 10000 | P15: 10000 | Q15: 10000 | R15: 10000 | S15: =SUM(G15:R15) -> 80000 | T15: =D15*2 -> 12000 | U15: =SUM(K15:R15) -> 80000 | V15: 0 | W15: 0 | X15: 0 | Y15: 0 | Z15: 0 | AA15: 0 | AB15: 0 | AC15: 0 | AD15: 0 | AE15: 0 | AF15: 0 | AG15: 0 | AH15: 0 | AJ15: =SUM(W15:AH15) -> 0
A16: 15 | B16: Ahtesham Mohammed | C16: Qlik Sense | D16: 30000 | E16: 10000 | F16: Akbar sir | G16: 6000 | H16: 6000 | I16: 4650 | J16: 5429 | K16: 5000 | L16: 0 | M16: 0 | N16: 0 | O16: 0 | P16: 0 | Q16: 0 | R16: 0 | S16: =SUM(G16:R16) -> 27079 | T16: 60000 | U16: =SUM('2022'!L16:R16)+'2021'!AL24 -> 12000 | V16: 0 | W16: =G16 -> 6000 | X16: =H16 -> 6000 | Y16: =I16 -> 4650 | Z16: 5429 | AA16: =K16 -> 5000 | AB16: 0 | AC16: 0 | AD16: 0 | AE16: 0 | AF16: 0 | AG16: 0 | AH16: 0 | AJ16: =SUM(W16:AH16) -> 27079
A17: 16 | B17: Krushna Rauda | C17: Qlik Sense | D17: 15000 | E17: 10000 | F17: Akbar sir | G17: NA | H17: =E17/23*9 -> 3913.0435 | I17: 10000 | J17: 10000 | K17: =E17/22*17 -> 7727.2727 | L17: 10000 | M17: 10000 | N17: 10000 | O17: 10000 | P17: =10000/21*17 -> 8095.2381 | Q17: =10000/23*18 -> 7826.087 | R17: 10000 | S17: =SUM(G17:R17) -> 97561.641 | T17: 60000 | U17: =SUM(H17:R17) -> 97561.641 | V17: 0 | W17: 0 | X17: 0 | Y17: 0 | Z17: 0 | AA17: 0 | AB17: 0 | AC17: 0 | AD17: 0 | AE17: 0 | AF17: 0 | AG17: 0 | AH17: 0 | AJ17: =SUM(W17:AH17) -> 0
A18: 17 | B18: Warfan ahmed khan | C18: Qlik Sense | D18: 14000 | E18: 6000 | F18: Akbar sir | G18: 6000 | H18: =E18/23*18 -> 4695.6522 | I18: =E18/20*10 -> 3000 | J18: =I18 -> 3000 | K18: 0 | L18: 0 | M18: =E18/20*14 -> 4200 | N18: =E18/23*19 -> 4956.5217 | O18: =E18-1272 -> 4728 | P18: 4000 | Q18: =6000/23*16.5 -> 4304.3478 | R18: =E18/21*8 -> 2285.7143 | S18: =SUM(G18:R18) -> 41170.236 | T18: =D18*2 -> 28000 | U18: 29000 | V18: 0 | W18: 0 | X18: =H18 -> 4695.6522 | Y18: =I18 -> 3000 | Z18: =J18 -> 3000 | AA18: =K18 -> 0 | AB18: =L18 -> 0 | AC18: =M18 -> 4200 | AD18: =N18 -> 4956.5217 | AE18: =O18 -> 4728 | ... AH18: =R18 -> 2285.7143 | AI18: a | AJ18: =SUM(W18:AH18) -> 35170.236
A19: 18 | B19: Saif Khan | C19: Qlik sense | D19: 10000 | E19: 6000 | F19: Akbar sir | G19: NA | H19: NA | I19: NA | J19: NA | K19: NA | L19: NA | M19: NA | N19: NA | O19: NA | P19: =E19/21*12 -> 3428.5714 | Q19: 6000 | R19: 6000 | S19: =SUM(G19:R19) -> 15428.571 | T19: =D19*2 -> 20000 | U19: =SUM(P19:R19) -> 15428.571 | V19: 0 | AF19: 0 | AG19: 0 | AH19: 0 | AJ19: =SUM(W19:AH19) -> 0
A20: 19 | B20: Sana Choudhary | C20: Sales | D20: 10000 | E20: 10000 | F20: Akbar sir | G20: 5000 | H20: 5000 | I20: 5000 | J20: =I20 -> 5000 | K20: 5000 | L20: 7000 | M20: 10000 | N20: =E20/23*20 -> 8695.6522 | O20: 10000 | P20: 10000 | Q20: 10000 | R20: =E20/22*16 -> 7272.7273 | S20: =SUM(G20:R20) -> 87968.379 | T20: =D20*2 -> 20000 | U20: ='2021'!AL29+'2022'!G20+'2022'!H20 -> 20727.273 | V20: 0 | W20: 0 | X20: 0 | Y20: =I20 -> 5000 | Z20: =J20 -> 5000 | AA20: =K20 -> 5000 | AB20: =L20 -> 7000 | AC20: 10000 | AD20: =N20 -> 8695.6522 | AE20: =O20 -> 10000 | AF20: =P20 -> 10000 | AG20: =Q20 -> 10000 | AH20: =R20 -> 7272.7273 | AI20: a | AJ20: =SUM(W20:AH20) -> 77968.379
A21: 20 | B21: Hajra Shaikh | C21: Sales | D21: 6000 | E21: 6000 | F21: Akbar sir | G21: 5000 | H21: =E21/23*19 -> 4956.5217 | I21: 5500 | J21: 5500 | K21: 6000 | L21: 4000 | M21: 4000 | N21: 5000 | O21: 6000 | P21: 3000 | Q21: 4000 | R21: 4000 | S21: =SUM(G21:R21) -> 56956.522 | T21: =D21*2 -> 12000 | U21: =SUM(G21:I21) -> 15456.522 | V21: 0 | W21: 0 | X21: 0 | Y21: 0 | Z21: 5500 | AA21: =K21 -> 6000 | AB21: =L21 -> 4000 | AC21: 4000 | AD21: =N21 -> 5000 | AE21: =O21 -> 6000 | AF21: =P21 -> 3000 | AG21: =Q21 -> 4000 | AH21: =R21 -> 4000 | AI21: a | AJ21: =SUM(W21:AH21) -> 41500
A22: 21 | B22: Shariqa Lashkar | C22: Sales | D22: 6000 | E22: 6000 | F22: Akbar sir | G22: NA | H22: NA | I22: NA | J22: NA | K22: NA | L22: NA | M22: NA | N22: NA | O22: 6000 | P22: 6000 | Q22: 4500 | R22: 6000 | S22: =SUM(G22:R22) -> 22500 | T22: =D22*2 -> 12000 | U22: =SUM(O22:R22) -> 22500 | V22: 0 | AE22: 0 | AF22: 0 | AG22: =Q22 -> 4500 | AH22: =R22 -> 6000 | AI22: a | AJ22: =SUM(W22:AH22) -> 10500
A23: 22 | B23: Tehmina Hamduley | C23: Sales | D23: 6000 | E23: 6000 | F23: Akbar sir | G23: NA | H23: NA | I23: NA | J23: NA | K23: NA | L23: NA | M23: NA | N23: NA | O23: 3000 | P23: 4500 | Q23: 4500 | R23: 4500 | S23: =SUM(G23:R23) -> 16500 | T23: =D23*2 -> 12000 | U23: =SUM(O23:R23) -> 16500 | V23: 0 | AE23: 0 | AF23: 0 | AG23: 0 | AH23: =R23 -> 4500 | AI23: a | AJ23: =SUM(W23:AH23) -> 4500
A24: 23 | B24: Yasmeen Shaikh | C24: Sales | D24: 6000 | E24: 6000 | F24: Akbar sir | G24: NA | H24: NA | I24: NA | J24: NA | K24: NA | L24: NA | M24: NA | N24: NA | O24: 6000 | P24: 6000 | Q24: 6000 | R24: 6000 | S24: =SUM(G24:R24) -> 24000 | T24: =D24*2 -> 12000 | U24: =SUM(O24:R24) -> 24000 | V24: 0 | AE24: 0 | AF24: 0 | AG24: =Q24 -> 6000 | AH24: =R24 -> 6000 | AI24: a | AJ24: =SUM(W24:AH24) -> 12000
A25: 24 | B25: Sadat sir | C25: Sales | D25: 3500AED | E25: 3500AED | F25: Akbar sir | G25: NA | H25: NA | I25: NA | J25: NA | K25: NA | L25: NA | M25: NA | N25: NA | O25: =3500/22*12 -> 1909.0909 | P25: 2000 | Q25: 2000 | R25: 0 | S25: =SUM(O25:R25) -> 5909.0909 | V25: 0 | AF25: 0 | AG25: 0 | AH25: 0 | AJ25: =SUM(W25:AH25) -> 0
A26: 25 | B26: Mohammad Rehanuddin | C26: Salesforce admin | D26: 52000 | E26: 5000 | F26: Akbar sir | G26: 1591 | H26: 5000 | I26: 5000 | J26: =I26 -> 5000 | K26: 5000 | L26: =E26/23*8 -> 1739.1304 | M26: 5000 | N26: 5000 | O26: 5000 | P26: 5000 | Q26: 5000 | R26: 5000 | S26: =SUM(G26:R26) -> 53330.13 | T26: =D26*2 -> 104000 | U26: ='On hold bonus'!B4+SUM(P26:R26) -> 105000 | V26: 0 | W26: =G26 -> 1591 | X26: =H26 -> 5000 | Y26: =I26 -> 5000 | Z26: =J26 -> 5000 | AA26: 5000 | AB26: 0 | AC26: 0 | AD26: 0 | AE26: 0 | AF26: 0 | AG26: 0 | AH26: 0 | AJ26: =SUM(W26:AH26) -> 21591
A27: 26 | B27: Basit Khan | C27: Salesforce admin | D27: 10000 | E27: 6000 | F27: Akbar sir | G27: NA | H27: NA | I27: NA | J27: NA | K27: NA | L27: NA | M27: NA | N27: NA | O27: =E27/22*17 -> 4636.3636 | P27: 6000 | Q27: 5000 | R27: 5000 | S27: =SUM(O27:R27) -> 20636.364 | T27: =D27*2 -> 20000 | U27: =SUM(O27:R27) -> 20636.364 | V27: 0 | AE27: 0 | AF27: 0 | AG27: 0 | AH27: 0 | AJ27: =SUM(W27:AH27) -> 0
A28: 27 | B28: Naeem imran | C28: Salesforce admin | D28: 10000 | E28: 6000 | F28: Akbar sir | G28: NA | H28: NA | I28: NA | J28: NA | K28: NA | L28: NA | M28: NA | N28: NA | O28: NA | P28: 6000 | Q28: 5000 | R28: 5000 | S28: =SUM(O28:R28) -> 16000 | T28: =D28*2 -> 20000 | U28: =SUM(P28:R28) -> 16000 | V28: 0 | W28: =G28 -> NA | X28: =H28 -> NA | Y28: =I28 -> NA | Z28: =J28 -> NA | AA28: =K28 -> NA | AB28: =L28 -> NA | AC28: =M28 -> NA | AD28: =N28 -> NA | ... AH28: =R28 -> 5000 | AJ28: =SUM(W28:AH28) -> 16000
A29: 28 | B29: Asbiya Sadaf | C29: Salesforce admin | D29: 10000 | E29: 6000 | F29: Akbar sir | G29: NA | H29: NA | I29: NA | J29: NA | K29: NA | L29: NA | M29: NA | N29: NA | O29: =E29/22*15 -> 4090.9091 | P29: 6000 | Q29: 5000 | R29: 6000 | S29: =SUM(O29:R29) -> 21090.909 | T29: =D29*2 -> 20000 | U29: =SUM(O29:R29) -> 21090.909 | V29: 0 | AE29: 0 | AF29: 0 | AG29: 0 | AH29: 0 | AJ29: =SUM(W29:AH29) -> 0
A30: 29 | B30: Saniya Shaikh | C30: Salesforce admin | D30: 6000 | E30: 10000 | F30: Akbar sir | G30: NA | H30: NA | I30: NA | J30: NA | K30: NA | L30: NA | M30: NA | N30: NA | O30: NA | P30: NA | Q30: NA | R30: 9000 | S30: =SUM(O30:R30) -> 9000 | T30: =D30*2 -> 12000 | U30: =SUM(O30:R30) -> 9000 | V30: 0 | AE30: 0 | AF30: 0 | AG30: 0 | AH30: 0 | AJ30: =SUM(W30:AH30) -> 0
A31: 30 | B31: Naheed | C31: Salesforce Technical | D31: 6000 | E31: 10000 | F31: Akbar sir | G31: NA | H31: NA | I31: NA | J31: NA | K31: NA | L31: NA | M31: =E31/20*7 -> 3500 | N31: 10000 | O31: 10000 | P31: 5000 | Q31: 7000 | R31: 5000 | S31: =SUM(O31:R31) -> 27000 | T31: =D31*2 -> 12000 | U31: =SUM(M31:R31) -> 40500 | V31: 0 | AC31: 0 | AD31: 0 | AE31: 0 | AF31: 0 | AG31: 0 | AH31: 0 | AJ31: =SUM(W31:AH31) -> 0
A32: 31 | B32: Nazmin | C32: Salesforce Technical | D32: 6000 | E32: 10000 | F32: Akbar sir | G32: NA | H32: NA | I32: NA | J32: NA | K32: NA | L32: NA | M32: =E32/20*5 -> 2500 | N32: 10000 | O32: 10000 | P32: 9000 | Q32: 10000 | R32: 8000 | S32: =SUM(O32:R32) -> 37000 | T32: =D32*2 -> 12000 | U32: =SUM(M32:R32) -> 49500 | V32: 0 | AC32: 0 | AD32: 0 | AE32: 0 | AF32: 0 | AG32: 0 | AH32: 0 | AJ32: =SUM(W32:AH32) -> 0
A33: 32 | B33: Akbar | C33: Salesforce Technical | D33: 6000 | E33: 10000 | F33: Akbar sir | G33: NA | H33: NA | I33: NA | J33: NA | K33: NA | L33: NA | M33: =E33/20*5 -> 2500 | N33: 10000 | O33: 10000 | P33: 5000 | Q33: 7000 | R33: 5000 | S33: =SUM(O33:R33) -> 27000 | T33: =D33*2 -> 12000 | U33: =SUM(M33:R33) -> 39500 | V33: 0 | AC33: 0 | AD33: 0 | AE33: 0 | AF33: 0 | AG33: 0 | AH33: 0 | AJ33: =SUM(W33:AH33) -> 0
A34: 33 | B34: Afroz Khan | C34: Salesforce Technical | D34: 10000 | E34: 6000 | F34: Akbar sir | G34: NA | H34: NA | I34: NA | J34: NA | K34: NA | L34: NA | M34: NA | N34: 6000 | O34: 6000 | P34: 6000 | Q34: 6000 | R34: 6000 | S34: =SUM(O34:R34) -> 24000 | T34: =D34*2 -> 20000 | U34: =SUM(O34:R34) -> 24000 | V34: 0 | AE34: 0 | AF34: 0 | AG34: 0 | AH34: 0 | AJ34: =SUM(W34:AH34) -> 0
A35: 34 | B35: Shaikh Zeeshan Shaikh Rafeeque | C35: Salesforce-Eienstein | D35: 40000 | E35: 10000 | F35: Akbar sir | G35: 5000 | H35: 5000 | I35: 5000 | J35: =I35 -> 5000 | K35: 5000 | L35: 5000 | M35: 5000 | N35: 5000 | O35: 10000 | P35: 10000 | Q35: 10000 | R35: =E35/21*12 -> 5714.2857 | S35: =SUM(G35:R35) -> 75714.286 | T35: =D35*2 -> 80000 | U35: ='On hold bonus'!B48 -> 108826 | W35: 0 | X35: 0 | Y35: 0 | Z35: 0 | AA35: 0 | AB35: 5000 | AC35: =M35 -> 5000 | AD35: =N35 -> 5000 | AE35: =O35 -> 10000 | AF35: =P35 -> 10000 | AG35: =Q35 -> 10000 | AH35: =R35 -> 5714.2857 | AI35: a | AJ35: =SUM(W35:AH35) -> 50714.286 | AK35: =S35-AB35-AC35-AD35-AE35-AF35-AG35-AH35 -> 25000 | AL35: 29826.087 | AN35: =SUM(AK35:AL35) -> 54826.087
A36: 35 | B36: Shaikh Samee | C36: Salesforce-Eienstein | D36: 25000 | E36: 5000 | F36: Akbar sir | G36: 4000 | H36: 4000 | I36: 4000 | J36: =D36/21*6 -> 7142.8571 | K36: 4000 | L36: 3500 | M36: 3500 | N36: 5000 | O36: 5000 | P36: 5000 | Q36: 5000 | R36: 5000 | S36: =SUM(G36:R36) -> 55142.857 | T36: =D36*2 -> 50000 | U36: ='2021'!AL42+G36+H36 -> 24782.609 | V36: 0 | W36: 0 | X36: 0 | Y36: =I36 -> 4000 | Z36: 3429 | AA36: =K36 -> 4000 | AB36: =L36 -> 3500 | AC36: =M36 -> 3500 | AD36: =N36 -> 5000 | AE36: =O36 -> 5000 | AF36: 0 | AG36: 0 | AH36: 15000 | AI36: a | AJ36: =SUM(W36:AH36) -> 43429
A37: 36 | B37: Minhaj mohammed | C37: Sharepoint | D37: 6000 | E37: 10000 | F37: Akbar sir | G37: NA | H37: NA | I37: NA | J37: NA | K37: NA | L37: 3000 | M37: 10000 | N37: 10000 | O37: 10000 | P37: 10000 | Q37: 10000 | R37: 7000 | S37: =SUM(G37:R37) -> 60000 | T37: =D37*2 -> 12000 | U37: =SUM(L37:R37) -> 60000 | V37: =0 -> 0 | AB37: 0 | AC37: 0 | AD37: 0 | AE37: 0 | AF37: 0 | AG37: 0 | AH37: 0 | AJ37: =SUM(W37:AH37) -> 0
A38: 37 | B38: Ansari Mohammed Arshduddin Mohammed Masooduddin | C38: SharePoint | D38: 30000 | E38: 5000 | F38: Akbar sir | G38: 6000 | H38: 6000 | I38: 6000 | J38: =I38 -> 6000 | K38: =J38 -> 6000 | L38: 6000 | M38: 6000 | N38: 6000 | O38: 5000 | P38: =E38/21*6 -> 1428.5714 | Q38: 5000 | R38: 4000 | S38: =SUM(G38:R38) -> 63428.571 | T38: =D38*2 -> 60000 | U38: =(28500-6000)+SUM(O38:R38) -> 37928.571 | V38: 0 | W38: =G38 -> 6000 | X38: =H38 -> 6000 | Y38: =I38 -> 6000 | Z38: =J38 -> 6000 | AA38: =K38 -> 6000 | AB38: =L38 -> 6000 | AC38: =M38 -> 6000 | AD38: =N38 -> 6000 | AE38: =O38 -> 5000 | AF38: 0 | AG38: 0 | AH38: 0 | AJ38: =SUM(W38:AH38) -> 53000
A39: 38 | B39: Nagma Khan | C39: SharePoint | D39: 17000 | E39: 10000 | F39: Akbar sir | G39: 10000 | H39: 10000 | I39: 10000 | J39: =I39 -> 10000 | K39: =J39 -> 10000 | L39: 10000 | M39: 10000 | N39: 10000 | O39: 10000 | P39: 10000 | Q39: 10000 | R39: 10000 | S39: =SUM(G39:R39) -> 120000 | T39: =D39*2 -> 34000 | U39: 36000 | V39: 0 | W39: 10000 | X39: =H39 -> 10000 | Y39: =I39 -> 10000 | Z39: =J39 -> 10000 | AA39: =K39 -> 10000 | AB39: =L39 -> 10000 | AC39: =M39 -> 10000 | AD39: =N39 -> 10000 | AE39: =O39 -> 10000 | ... AH39: =R39 -> 10000 | AI39: a | AJ39: =SUM(W39:AH39) -> 120000
